I'm sorry, but an uncaught exception occurred.

While running game code:
  File "game/auction.rpy", line 77, in script
    auctioneer "GOING ONCE. GOING TWICE... "
Exception: Sayer 'auctioneer' is not defined.

-- Full Traceback ------------------------------------------------------------

Full traceback:
  File "game/auction.rpy", line 77, in script
    auctioneer "GOING ONCE. GOING TWICE... "
  File "C:\Users\azcun\Downloads\renpy-8.2.1-sdk\renpy\ast.py", line 2557, in execute
    Say.execute(self)
  File "C:\Users\azcun\Downloads\renpy-8.2.1-sdk\renpy\ast.py", line 575, in execute
    who = eval_who(self.who, self.who_fast)
  File "C:\Users\azcun\Downloads\renpy-8.2.1-sdk\renpy\ast.py", line 464, in eval_who
    raise Exception("Sayer '%s' is not defined." % who)
Exception: Sayer 'auctioneer' is not defined.

Windows-10-10.0.22631 AMD64
Ren'Py 8.2.1.24030407
The Exhibition 1.0
Tue May 28 19:00:53 2024
